(py3_venv) [ponnathan@pylab36b lessons]$ ipython -i cl6_ls3_pyeapi_api.py 
Python 3.11.6 (main, Oct  4 2023, 18:55:41) [GCC 11.4.1 20230605 (Red Hat 11.4.1-2)]
Type 'copyright', 'credits' or 'license' for more information
IPython 7.31.1 -- An enhanced Interactive Python. Type '?' for help.
Password: 
Enable: 
<pyeapi.api.vlans.Vlans object at 0x7fc73a4f2810>

In [1]: device
Out[1]: Node(connection=EapiConnection(transport=https://arista8.lasthop.io:443//command-api))

In [2]: vlan_cfg
Out[2]: <pyeapi.api.vlans.Vlans at 0x7fc73a4f2810>

In [3]: help(device.api)


In [4]: device.api("bgp")
Out[4]: <pyeapi.api.bgp.Bgp at 0x7fc7396fdf10>

In [5]: device.api("acl")
Out[5]: <pyeapi.api.acl.Acls at 0x7fc7397dd450>

In [6]: vlan_cfg
Out[6]: <pyeapi.api.vlans.Vlans at 0x7fc73a4f2810>

In [7]: vlan_cfg.get(1)
Out[7]: {'vlan_id': '1', 'name': 'default', 'state': 'active', 'trunk_groups': []}

In [8]: vlan_cfg
Out[8]: <pyeapi.api.vlans.Vlans at 0x7fc73a4f2810>

In [9]: vlan_cfg.create(800)
Out[9]: True

In [10]: vlan_cfg.create(801)
Out[10]: True

In [11]: vlan_cfg.create(802)
Out[11]: True

In [12]: vlan_cfg.create(800, "blue")
---------------------------------------------------------------------------
TypeError                                 Traceback (most recent call last)
<ipython-input-12-e8055fc14b22> in <module>
----> 1 vlan_cfg.create(800, "blue")

TypeError: Vlans.create() takes 2 positional arguments but 3 were given

In [13]: vlan_cfg.set_name(800, "blue")
Out[13]: True

In [14]: vlan_cfg.set_name(801, "red")
Out[14]: True

In [15]: vlan_cfg.set_name(802, "green")
Out[15]: True

In [16]: quit
(py3_venv) [ponnathan@pylab36b lessons]$ 
